<!DOCTYPE html>
<html lang="en">
  <head>
    <meta charset="UTF-8" />
    <meta http-equiv="X-UA-Compatible" content="IE=edge" />
    <meta name="viewport" content="width=device-width, initial-scale=1.0" />
    <title>Promise API</title>
  </head>
  <body>
    <script>
      /**
       * Promise对象的状态改变，只有两种可能：从pending变为fulfilled和从pending变为rejected。
       * 只要这两种情况发生，状态就凝固了，不会再变了，会一直保持这个结果，这时就称为 resolved（已定型）。
       * 如果改变已经发生了，你再对Promise对象添加回调函数，也会立即得到这个结果。
       * 这与事件（Event）完全不同，事件的特点是，如果你错过了它，再去监听，是得不到结果的。
       */
      let p = new Promise((resolve, reject) => {
        // 同步调用
        console.log(1)
        reject('sorry')
      })

      console.log(2)

      // 执行 then 方法
      // p.then(
      //   value => {
      //     console.log(value)
      //   },
      //   reason => {
      //     console.log(reason)
      //   }
      // )

      // 执行 catch 方法
      // catch 方法是对 then 方法的封装,只用于接收 reject(reason) 中的错误信息
      p.catch(reason => {
        console.log(reason)
      })

      /**
       * Promise.resolve 方法
       * 如果参数非 Promise 对象，则返回结果为成功 Promise 对象
       * 如果参数是 Promise 对象，则参数的返回结果决定了 resolve 的结果
       */
      let p1 = Promise.resolve(3)
      console.log(p1) //Promise {<fulfilled>: 3}

      let p2 = Promise.resolve(
        new Promise((resolve, reject) => {
          // resolve('OK')
          reject('Error')
        })
      )
      console.log(p2) // Promise {<rejected>: 'Error'}
      p2.catch(reason => {
        console.log(reason)
      })

      /**
       * Promise.reject 方法
       * 返回一个失败的 Promise 对象
       */
      // let p3 = Promise.reject(4)
      let p3 = Promise.reject(
        new Promise((resolve, reject) => {
          resolve('yes')
        })
      )
      p3.catch(reason => {
        console.log(reason) // Promise {<fulfilled>: 'yes'}
      })

      /**
       * Promise.all 方法
       * 用于将多个 Promise 实例,包装成一个新的 Promise 实例
       * var p=Promise.all([p1,p2,p3]);
       * （1）只有p1、p2、p3的状态都变成fulfilled，p的状态才会变成fulfilled，此时p1、p2、p3的返回值组成一个数组，传递给p的回调函数。
       * （2）只要p1、p2、p3之中有一个被rejected，p的状态就变成rejected，此时第一个被reject的实例的返回值，会传递给p的回调函数。
       */
      let p4 = new Promise((resolve, reject) => {
        resolve('成功了')
      })

      let p5 = new Promise((resolve, reject) => {
        resolve('success')
      })

      let p6 = Promise.reject('失败')

      Promise.all([p4, p5])
        .then(result => {
          console.log(result) // ['成功了', 'success']
        })
        .catch(error => {
          console.log(error)
        })

      Promise.all([p4, p6, p5])
        .then(result => {
          console.log(result)
        })
        .catch(error => {
          console.log(error) // 失败
        })
      /**
       * 需要特别注意的是，Promise.all获得的成功结果的数组里面的数据顺序和
       * Promise.all接收到的数组顺序是一致的，即p1的结果在前，即便p1的结果
       * 获取的比p2要晚。这带来了一个绝大的好处：在前端开发请求数据的过程中，
       * 偶尔会遇到发送多个请求并根据请求顺序获取和使用数据的场景，
       * 使用Promise.all毫无疑问可以解决这个问题
       */
      let wake = time => {
        return new Promise((resolve, reject) => {
          setTimeout(() => {
            resolve(`${time / 1000}秒后醒来`)
          }, time)
        })
      }

      let p7 = wake(3000)
      let p8 = wake(2000)

      Promise.all([p7, p8])
        .then(result => {
          console.log(result) // [ '3秒后醒来', '2秒后醒来' ]
        })
        .catch(error => {
          console.log(error)
        })

      // 注意：如果作为参数的 Promise 实例，自己定义了catch方法，那么它一旦被rejected，
      // 并不会触发Promise.all()的catch方法。

      const p9 = new Promise((resolve, reject) => {
        resolve('hello')
      })
        .then(result => result)
        .catch(e => e)

      const p10 = new Promise((resolve, reject) => {
        throw new Error('报错了')
      })
        .then(result => result)
        .catch(e => e)

      Promise.all([p9, p10])
        .then(result => console.log(result)) // ["hello", Error: 报错了]
        .catch(e => console.log(e))

      // p1会resolved，p2首先会rejected，但是p2有自己的catch方法，该方法返回的是一个
      // 新的 Promise 实例，p2指向的实际上是这个实例。
      // 该实例执行完catch方法后，也会变成resolved，导致Promise.all()方法参数里面的两个实
      // 例都会resolved，因此会调用then方法指定的回调函数，而不会调用catch方法指定的回调函数。

      // 而如果p2没有自己的catch方法，就会调用Promise.all()的catch方法。如下：

      const p11 = new Promise((resolve, reject) => {
        resolve('hello')
      }).then(result => result)

      const p12 = new Promise((resolve, reject) => {
        throw new Error('报错了')
      }).then(result => result)

      Promise.all([p11, p12])
        .then(result => console.log(result))
        .catch(e => console.log(e)) // Error: 报错了

      /**
       * Promise.race 方法
       * Promise.race是赛跑的意思，也就是说Promise.race([p1, p2, p3])里面的结果哪个获取的快，
       * 就返回哪个结果，不管结果本身是成功还是失败
       * 使用场景: Promise.all和Promise.race都是有使用场景的。
       * 有些时候我们做一个操作可能得同时需要不同的接口返回的数据，这时我们就可以使用Promise.all；
       * 有时我们比如说有好几个服务器的好几个接口都提供同样的服务，我们不知道哪个接口更快，
       * 就可以使用Promise.race，哪个接口的数据先回来我们就用哪个接口的数据
       */
      let p13 = new Promise((resolve, reject) => {
        setTimeout(() => {
          resolve('success')
        }, 1000)
      })

      let p14 = new Promise((resolve, reject) => {
        setTimeout(() => {
          reject('failed')
        }, 500)
      })

      Promise.race([p13, p14])
        .then(result => {
          console.log(result)
        })
        .catch(error => {
          console.log(error) // failed
        })
    </script>
  </body>
</html>
